Workbook

Sheet Read Me
A1: Saltaire Softball League — Stats Workbook
A2: Generated from ssl_data.json (interactive stats site dataset).
A3: Seasons 2019–2026 (no 2020). Compiled from GameChanger box scores.
A5: Sheets | B5: Batting/Pitching by Season & Career, Team by Season & Career
A6: Season sheets | B6: one row per player per team per season (ledger rows aggregated)
A8: ERA basis | B8: ALL ERA shown on a 7-inning basis (earned runs per complete 7-inning game).
A9: Individual pitching | B9: ERA = ER × 7 / IP
A10: Team ERA | B10: stored 9-inning value scaled × 7/9 to match (all sheets are 7-inning)
A11: IP notation | B11: Individual pitchers use baseball thirds (.1 = ⅓, .2 = ⅔); team IP is decimal innings
A12: Rates | B12: AVG=H/AB · OBP=(H+BB)/(AB+BB) · SLG=TB/AB · OPS=OBP+SLG · ISO=SLG−AVG
B13: TB=1B+2·2B+3·3B+4·HR · XBH=2B+3B+HR · WHIP=(H+BB)/IP · K/7, BB/7 per 7 innings
A15: Note | B15: A player entered under two scorekeeper spellings may appear more than once.
A16: Note | B16: This workbook is a snapshot; the Drive ssl_stats.xlsx is separate and unchanged.
A18: Update 2026-08-14 | B18: Added 4 games from box-score PDFs: Dragons_vs_Dogfish_Aug_2, Bulkheads_vs_Outsiders_Aug_8, Excitables_vs_Dogfish_Aug_8, RipTide_vs_Dragons_Aug_9. New Dogfish players kept verbatim: A Pitcher, A Female, A Adams, B Coffey, Alex Newman. M Valente #6=Mike, #8=Mark (per user). Dragons 2026 team ERA re-footed to pitching rows.
A19: Update 2026-08-14 (2) | B19: Split conflated "L Bender" (Fringe) into Lenny Bender (#13, the pitcher) and Leila Bender (joined 2024; usually bats 10th+). 2018-2023 rows are all Lenny. 2026 web-import rows assigned to Lenny per user. Merged Fringe_vs_Dogfish_Aug_7_2026 (future-dated, played Aug 1-2 weekend): Fringe 8-3 Dogfish; its L Bender #13 batting 10th = Leila per user. CR: L Bender renamed CR: Leila Bender. Fixed corrupted Years cell on M Mederick career row.
A20: Update 2026-08-20 | B20: Added 2 games: Excitables_vs_RipTide_May_24_2026 (backfill, 4-inning mercy, EXCT 23-1) and Fringe_vs_Bulkheads_Aug_15_2026 (BLKH 14-1). A McAllister and H McAllister CONFIRMED BY USER as two different players — H McAllister's 2026 rows left untouched; Aug-15 "A Mcallister #33" opened a new 2026 season row for A McAllister (his first since 2025). New: N Modico (RipTide, verbatim per user); Patrick 2026 season row; first-ever pitching rows for W Starkey and R Tirone (RipTide) and a 2026 pitching row for C Butler (Fringe). Fringe L Bender split applied: #13/(P) = Lenny, untagged 11th = Leila. Career rows updated by delta only; pre-existing season-vs-career drift left untouched per user.
A21: Update 2026-08-21 | B21: Added Dogfish_vs_Bulkheads_Aug_16_2026 (BLKH 5-4). Dogfish "A Out" placeholder normalized to the existing "Auto Out" name per user (it is the short-lineup automatic out, not a player; kept so team AB still foots to 33). New 2026 season rows: Auto Out (Dogfish), C Karp (Bulkheads). A Mcallister #33 -> A McAllister. Career rows updated by delta only.

Sheet Batting by Season
A1: Season | B1: Team | C1: Player | D1: G | E1: AB | F1: R | G1: H | H1: 2B | I1: 3B | J1: HR | K1: XBH | L1: TB | M1: RBI | N1: BB | O1: SO | P1: AVG | Q1: OBP | R1: SLG | S1: OPS | T1: ISO
A2: 2026 | B2: Bulkheads | C2: B Karp | D2: 12 | E2: 41 | F2: 20 | G2: 20 | H2: 1 | I2: 0 | J2: 8 | K2: 9 | L2: 45 | M2: 15 | N2: 4 | O2: 0 | P2: =IF(E2=0,0,G2/E2) -> 0.48780488 | Q2: =IF(E2+N2=0,0,(G2+N2)/(E2+N2)) -> 0.53333333 | R2: =IF(E2=0,0,L2/E2) -> 1.097561 | S2: =R2+Q2 -> 1.6308943 | T2: =R2-P2 -> 0.6097561
A3: 2026 | B3: Bulkheads | C3: J Metzler | D3: 12 | E3: 34 | F3: 9 | G3: 13 | H3: 1 | I3: 0 | J3: 5 | K3: 6 | L3: 29 | M3: 17 | N3: 4 | O3: 0 | P3: =IF(E3=0,0,G3/E3) -> 0.38235294 | Q3: =IF(E3+N3=0,0,(G3+N3)/(E3+N3)) -> 0.44736842 | R3: =IF(E3=0,0,L3/E3) -> 0.85294118 | S3: =R3+Q3 -> 1.3003096 | T3: =R3-P3 -> 0.47058824
A4: 2026 | B4: Bulkheads | C4: S Karp | D4: 9 | E4: 27 | F4: 8 | G4: 12 | H4: 8 | I4: 0 | J4: 1 | K4: 9 | L4: 23 | M4: 4 | N4: 3 | O4: 1 | P4: =IF(E4=0,0,G4/E4) -> 0.44444444 | Q4: =IF(E4+N4=0,0,(G4+N4)/(E4+N4)) -> 0.5 | R4: =IF(E4=0,0,L4/E4) -> 0.85185185 | S4: =R4+Q4 -> 1.3518519 | T4: =R4-P4 -> 0.40740741
A5: 2026 | B5: Bulkheads | C5: D Swiedler | D5: 11 | E5: 36 | F5: 10 | G5: 10 | H5: 0 | I5: 0 | J5: 0 | K5: 0 | L5: 10 | M5: 0 | N5: 3 | O5: 0 | P5: =IF(E5=0,0,G5/E5) -> 0.27777778 | Q5: =IF(E5+N5=0,0,(G5+N5)/(E5+N5)) -> 0.33333333 | R5: =IF(E5=0,0,L5/E5) -> 0.27777778 | S5: =R5+Q5 -> 0.61111111 | T5: =R5-P5 -> 0
A6: 2026 | B6: Bulkheads | C6: N Schlackman | D6: 11 | E6: 36 | F6: 10 | G6: 14 | H6: 6 | I6: 0 | J6: 0 | K6: 6 | L6: 20 | M6: 13 | N6: 4 | O6: 1 | P6: =IF(E6=0,0,G6/E6) -> 0.38888889 | Q6: =IF(E6+N6=0,0,(G6+N6)/(E6+N6)) -> 0.45 | R6: =IF(E6=0,0,L6/E6) -> 0.55555556 | S6: =R6+Q6 -> 1.0055556 | T6: =R6-P6 -> 0.16666667
A7: 2026 | B7: Bulkheads | C7: B Feeley | D7: 13 | E7: 38 | F7: 2 | G7: 7 | H7: 0 | I7: 0 | J7: 2 | K7: 2 | L7: 13 | M7: 7 | N7: 2 | O7: 1 | P7: =IF(E7=0,0,G7/E7) -> 0.18421053 | Q7: =IF(E7+N7=0,0,(G7+N7)/(E7+N7)) -> 0.225 | R7: =IF(E7=0,0,L7/E7) -> 0.34210526 | S7: =R7+Q7 -> 0.56710526 | T7: =R7-P7 -> 0.15789474
A8: 2026 | B8: Bulkheads | C8: J Carroll | D8: 6 | E8: 21 | F8: 4 | G8: 7 | H8: 2 | I8: 0 | J8: 1 | K8: 3 | L8: 12 | M8: 5 | N8: 3 | O8: 0 | P8: =IF(E8=0,0,G8/E8) -> 0.33333333 | Q8: =IF(E8+N8=0,0,(G8+N8)/(E8+N8)) -> 0.41666667 | R8: =IF(E8=0,0,L8/E8) -> 0.57142857 | S8: =R8+Q8 -> 0.98809524 | T8: =R8-P8 -> 0.23809524
A9: 2026 | B9: Bulkheads | C9: H McAllister | D9: 5 | E9: 12 | F9: 1 | G9: 3 | H9: 0 | I9: 0 | J9: 1 | K9: 1 | L9: 6 | M9: 2 | N9: 0 | O9: 1 | P9: =IF(E9=0,0,G9/E9) -> 0.25 | Q9: =IF(E9+N9=0,0,(G9+N9)/(E9+N9)) -> 0.25 | R9: =IF(E9=0,0,L9/E9) -> 0.5 | S9: =R9+Q9 -> 0.75 | T9: =R9-P9 -> 0.25
A10: 2026 | B10: Bulkheads | C10: C Feeley | D10: 14 | E10: 39 | F10: 1 | G10: 6 | H10: 0 | I10: 0 | J10: 0 | K10: 0 | L10: 6 | M10: 1 | N10: 1 | O10: 2 | P10: =IF(E10=0,0,G10/E10) -> 0.15384615 | Q10: =IF(E10+N10=0,0,(G10+N10)/(E10+N10)) -> 0.175 | R10: =IF(E10=0,0,L10/E10) -> 0.15384615 | S10: =R10+Q10 -> 0.32884615 | T10: =R10-P10 -> 0
A11: 2026 | B11: Bulkheads | C11: D Smith | D11: 12 | E11: 30 | F11: 6 | G11: 6 | H11: 3 | I11: 0 | J11: 0 | K11: 3 | L11: 9 | M11: 3 | N11: 9 | O11: 1 | P11: =IF(E11=0,0,G11/E11) -> 0.2 | Q11: =IF(E11+N11=0,0,(G11+N11)/(E11+N11)) -> 0.38461538 | R11: =IF(E11=0,0,L11/E11) -> 0.3 | S11: =R11+Q11 -> 0.68461538 | T11: =R11-P11 -> 0.1
A12: 2026 | B12: Bulkheads | C12: H Holton | D12: 11 | E12: 18 | F12: 2 | G12: 2 | H12: 0 | I12: 0 | J12: 0 | K12: 0 | L12: 2 | M12: 2 | N12: 3 | O12: 3 | P12: =IF(E12=0,0,G12/E12) -> 0.11111111 | Q12: =IF(E12+N12=0,0,(G12+N12)/(E12+N12)) -> 0.23809524 | R12: =IF(E12=0,0,L12/E12) -> 0.11111111 | S12: =R12+Q12 -> 0.34920635 | T12: =R12-P12 -> 0
A13: 2026 | B13: Bulkheads | C13: A Karp | D13: 11 | E13: 26 | F13: 3 | G13: 3 | H13: 0 | I13: 0 | J13: 0 | K13: 0 | L13: 3 | M13: 1 | N13: 4 | O13: 3 | P13: =IF(E13=0,0,G13/E13) -> 0.11538462 | Q13: =IF(E13+N13=0,0,(G13+N13)/(E13+N13)) -> 0.23333333 | R13: =IF(E13=0,0,L13/E13) -> 0.11538462 | S13: =R13+Q13 -> 0.34871795 | T13: =R13-P13 -> 0
... A1446: 2018 | B1446: RipTide | C1446: Sasha | D1446: 1 | E1446: 1 | F1446: 0 | G1446: 0 | H1446: 0 | I1446: 0 | J1446: 0 | K1446: 0 | L1446: 0 | M1446: 0 | N1446: 0 | O1446: 1 | P1446: =IF(E1446=0,0,G1446/E1446) -> 0 | Q1446: =IF(E1446+N1446=0,0,(G1446+N1446)/(E1446+N1446)) -> 0 | R1446: =IF(E1446=0,0,L1446/E1446) -> 0 | S1446: =R1446+Q1446 -> 0 | T1446: =R1446-P1446 -> 0

Sheet Batting Career
A1: Player | B1: Team | C1: Seasons | D1: Years | E1: G | F1: AB | G1: R | H1: H | I1: 2B | J1: 3B | K1: HR | L1: XBH | M1: TB | N1: RBI | O1: BB | P1: SO | Q1: AVG | R1: OBP | S1: SLG | T1: OPS | U1: ISO
A2: C Rouleau | B2: Clippers/Fringe | C2: 5 | D2: 2022, 2023, 2024, 2025, 2026 | E2: 57 | F2: 187 | G2: 87 | H2: 92 | I2: 10 | J2: 0 | K2: 43 | L2: 53 | M2: 231 | N2: 97 | O2: 22 | P2: 6 | Q2: =IF(F2=0,0,H2/F2) -> 0.49197861 | R2: =IF(F2+O2=0,0,(H2+O2)/(F2+O2)) -> 0.54545455 | S2: =IF(F2=0,0,M2/F2) -> 1.2352941 | T2: =S2+R2 -> 1.7807487 | U2: =S2-Q2 -> 0.74331551
A3: P Posilico | B3: Excitables | C3: 8 | D3: 2018,2019,2021,2022,2023,2024,2025,2026 | E3: 91 | F3: 257 | G3: 101 | H3: 101 | I3: 11 | J3: 1 | K3: 42 | L3: 54 | M3: 240 | N3: 104 | O3: 59 | P3: 17 | Q3: =IF(F3=0,0,H3/F3) -> 0.39299611 | R3: =IF(F3+O3=0,0,(H3+O3)/(F3+O3)) -> 0.50632911 | S3: =IF(F3=0,0,M3/F3) -> 0.93385214 | T3: =S3+R3 -> 1.4401813 | U3: =S3-Q3 -> 0.54085603
A4: T Valente | B4: Excitables | C4: 8 | D4: 2018,2019,2021,2022,2023,2024,2025,2026 | E4: 92 | F4: 234 | G4: 116 | H4: 94 | I4: 17 | J4: 0 | K4: 35 | L4: 52 | M4: 216 | N4: 89 | O4: 90 | P4: 11 | Q4: =IF(F4=0,0,H4/F4) -> 0.4017094 | R4: =IF(F4+O4=0,0,(H4+O4)/(F4+O4)) -> 0.56790123 | S4: =IF(F4=0,0,M4/F4) -> 0.92307692 | T4: =S4+R4 -> 1.4909782 | U4: =S4-Q4 -> 0.52136752
A5: R Smith | B5: Dogfish/Fringe | C5: 8 | D5: 2018,2019,2021,2022,2023,2024,2025,2026 | E5: 87 | F5: 246 | G5: 85 | H5: 85 | I5: 10 | J5: 1 | K5: 34 | L5: 45 | M5: 199 | N5: 70 | O5: 68 | P5: 6 | Q5: =IF(F5=0,0,H5/F5) -> 0.34552846 | R5: =IF(F5+O5=0,0,(H5+O5)/(F5+O5)) -> 0.48726115 | S5: =IF(F5=0,0,M5/F5) -> 0.80894309 | T5: =S5+R5 -> 1.2962042 | U5: =S5-Q5 -> 0.46341463
A6: B Karp | B6: Bulkheads | C6: 8 | D6: 2018,2019,2021,2022,2023,2024,2025,2026 | E6: 72 | F6: 214 | G6: 83 | H6: 93 | I6: 13 | J6: 0 | K6: 36 | L6: 49 | M6: 214 | N6: 89 | O6: 39 | P6: 2 | Q6: =IF(F6=0,0,H6/F6) -> 0.43457944 | R6: =IF(F6+O6=0,0,(H6+O6)/(F6+O6)) -> 0.52173913 | S6: =IF(F6=0,0,M6/F6) -> 1 | T6: =S6+R6 -> 1.5217391 | U6: =S6-Q6 -> 0.56542056
A7: B Ehlers | B7: Clippers | C7: 8 | D7: 2018,2019,2021,2022,2023,2024,2025,2026 | E7: 78 | F7: 228 | G7: 97 | H7: 101 | I7: 25 | J7: 2 | K7: 28 | L7: 55 | M7: 214 | N7: 83 | O7: 51 | P7: 4 | Q7: =IF(F7=0,0,H7/F7) -> 0.44298246 | R7: =IF(F7+O7=0,0,(H7+O7)/(F7+O7)) -> 0.54480287 | S7: =IF(F7=0,0,M7/F7) -> 0.93859649 | T7: =S7+R7 -> 1.4833994 | U7: =S7-Q7 -> 0.49561404
A8: A Darcy | B8: Excitables | C8: 8 | D8: 2018,2019,2021,2022,2023,2024,2025,2026 | E8: 84 | F8: 280 | G8: 77 | H8: 99 | I8: 8 | J8: 0 | K8: 24 | L8: 32 | M8: 179 | N8: 80 | O8: 14 | P8: 11 | Q8: =IF(F8=0,0,H8/F8) -> 0.35357143 | R8: =IF(F8+O8=0,0,(H8+O8)/(F8+O8)) -> 0.38435374 | S8: =IF(F8=0,0,M8/F8) -> 0.63928571 | T8: =S8+R8 -> 1.0236395 | U8: =S8-Q8 -> 0.28571429
A9: M Perna | B9: Outsiders | C9: 8 | D9: 2018,2019,2021,2022,2023,2024,2025,2026 | E9: 79 | F9: 228 | G9: 69 | H9: 82 | I9: 5 | J9: 0 | K9: 26 | L9: 31 | M9: 165 | N9: 70 | O9: 51 | P9: 10 | Q9: =IF(F9=0,0,H9/F9) -> 0.35964912 | R9: =IF(F9+O9=0,0,(H9+O9)/(F9+O9)) -> 0.47670251 | S9: =IF(F9=0,0,M9/F9) -> 0.72368421 | T9: =S9+R9 -> 1.2003867 | U9: =S9-Q9 -> 0.36403509
A10: C Butler | B10: Fringe | C10: 8 | D10: 2018,2019,2021,2022,2023,2024,2025,2026 | E10: 60 | F10: 186 | G10: 50 | H10: 65 | I10: 3 | J10: 0 | K10: 23 | L10: 26 | M10: 137 | N10: 56 | O10: 15 | P10: 7 | Q10: =IF(F10=0,0,H10/F10) -> 0.34946237 | R10: =IF(F10+O10=0,0,(H10+O10)/(F10+O10)) -> 0.39800995 | S10: =IF(F10=0,0,M10/F10) -> 0.73655914 | T10: =S10+R10 -> 1.1345691 | U10: =S10-Q10 -> 0.38709677
A11: C Striplin | B11: Clippers | C11: 8 | D11: 2018,2019,2021,2022,2023,2024,2025,2026 | E11: 62 | F11: 189 | G11: 52 | H11: 74 | I11: 3 | J11: 0 | K11: 23 | L11: 26 | M11: 146 | N11: 72 | O11: 24 | P11: 3 | Q11: =IF(F11=0,0,H11/F11) -> 0.39153439 | R11: =IF(F11+O11=0,0,(H11+O11)/(F11+O11)) -> 0.4600939 | S11: =IF(F11=0,0,M11/F11) -> 0.77248677 | T11: =S11+R11 -> 1.2325807 | U11: =S11-Q11 -> 0.38095238
A12: Mike Valente | B12: Excitables | C12: 8 | D12: 2018,2019,2021,2022,2023,2024,2025,2026 | E12: 97 | F12: 264 | G12: 75 | H12: 67 | I12: 7 | J12: 0 | K12: 22 | L12: 29 | M12: 140 | N12: 76 | O12: 61 | P12: 21 | Q12: =IF(F12=0,0,H12/F12) -> 0.25378788 | R12: =IF(F12+O12=0,0,(H12+O12)/(F12+O12)) -> 0.39384615 | S12: =IF(F12=0,0,M12/F12) -> 0.53030303 | T12: =S12+R12 -> 0.92414918 | U12: =S12-Q12 -> 0.27651515
A13: J Metzler | B13: Bulkheads | C13: 8 | D13: 2018,2019,2021,2022,2023,2024,2025,2026 | E13: 87 | F13: 251 | G13: 59 | H13: 87 | I13: 9 | J13: 0 | K13: 21 | L13: 30 | M13: 159 | N13: 76 | O13: 36 | P13: 11 | Q13: =IF(F13=0,0,H13/F13) -> 0.34661355 | R13: =IF(F13+O13=0,0,(H13+O13)/(F13+O13)) -> 0.42857143 | S13: =IF(F13=0,0,M13/F13) -> 0.63346614 | T13: =S13+R13 -> 1.0620376 | U13: =S13-Q13 -> 0.28685259
... A93: J Vail | B93: RipTide | C93: 3 | D93: 2024,2025,2026 | E93: 17 | F93: 48 | G93: 2 | H93: 7 | I93: 0 | J93: 0 | K93: 1 | L93: 1 | M93: 10 | N93: 5 | O93: 1 | P93: 3 | Q93: =IF(F93=0,0,H93/F93) -> 0.14583333 | R93: =IF(F93+O93=0,0,(H93+O93)/(F93+O93)) -> 0.16326531 | S93: =IF(F93=0,0,M93/F93) -> 0.20833333 | T93: =S93+R93 -> 0.37159864 | U93: =S93-Q93 -> 0.0625
A94: Justin: JO | B94: Dogfish | C94: 1 | D94: 2021 | E94: 8 | F94: 25 | G94: 4 | H94: 10 | I94: 2 | J94: 0 | K94: 1 | L94: =I94+J94+K94 -> 3 | M94: =H94+I94+2*J94+3*K94 -> 15 | N94: 7 | O94: 1 | P94: 0 | Q94: =IF(F94=0,0,H94/F94) -> 0.4 | R94: =IF(F94+O94=0,0,(H94+O94)/(F94+O94)) -> 0.42307692 | S94: =IF(F94=0,0,M94/F94) -> 0.6 | T94: =S94+R94 -> 1.0230769 | U94: =S94-Q94 -> 0.2
A95: Ryan | B95: RipTide | C95: 2 | D95: 2019,2021 | E95: 7 | F95: 22 | G95: 4 | H95: 5 | I95: 1 | J95: 0 | K95: 1 | L95: 2 | M95: 9 | N95: 3 | O95: 1 | P95: 0 | Q95: =IF(F95=0,0,H95/F95) -> 0.22727273 | R95: =IF(F95+O95=0,0,(H95+O95)/(F95+O95)) -> 0.26086957 | S95: =IF(F95=0,0,M95/F95) -> 0.40909091 | T95: =S95+R95 -> 0.66996047 | U95: =S95-Q95 -> 0.18181818
A96: John | B96: Dragons | C96: 1 | D96: 2023 | E96: 2 | F96: 7 | G96: 3 | H96: 4 | I96: 2 | J96: 0 | K96: 1 | L96: 3 | M96: 9 | N96: 1 | O96: 0 | P96: 0 | Q96: =IF(F96=0,0,H96/F96) -> 0.57142857 | R96: =IF(F96+O96=0,0,(H96+O96)/(F96+O96)) -> 0.57142857 | S96: =IF(F96=0,0,M96/F96) -> 1.2857143 | T96: =S96+R96 -> 1.8571429 | U96: =S96-Q96 -> 0.71428571
A97: Other Ryan | B97: Dogfish | C97: 1 | D97: 2019 | E97: 3 | F97: 10 | G97: 2 | H97: 4 | I97: 1 | J97: 0 | K97: 1 | L97: 2 | M97: 8 | N97: 4 | O97: 0 | P97: 0 | Q97: =IF(F97=0,0,H97/F97) -> 0.4 | R97: =IF(F97+O97=0,0,(H97+O97)/(F97+O97)) -> 0.4 | S97: =IF(F97=0,0,M97/F97) -> 0.8 | T97: =S97+R97 -> 1.2 | U97: =S97-Q97 -> 0.4
A98: H McAllister | B98: Bulkheads | C98: 1 | D98: 2026 | E98: 5 | F98: 12 | G98: 1 | H98: 3 | I98: 0 | J98: 0 | K98: 1 | L98: 1 | M98: 6 | N98: 2 | O98: 0 | P98: 1 | Q98: =IF(F98=0,0,H98/F98) -> 0.25 | R98: =IF(F98+O98=0,0,(H98+O98)/(F98+O98)) -> 0.25 | S98: =IF(F98=0,0,M98/F98) -> 0.5 | T98: =S98+R98 -> 0.75 | U98: =S98-Q98 -> 0.25
A99: Tom | B99: Dogfish | C99: 3 | D99: 2018,2019,2021 | E99: 8 | F99: 17 | G99: 2 | H99: 3 | I99: 0 | J99: 0 | K99: 1 | L99: 1 | M99: 6 | N99: 5 | O99: 3 | P99: 3 | Q99: =IF(F99=0,0,H99/F99) -> 0.17647059 | R99: =IF(F99+O99=0,0,(H99+O99)/(F99+O99)) -> 0.3 | S99: =IF(F99=0,0,M99/F99) -> 0.35294118 | T99: =S99+R99 -> 0.65294118 | U99: =S99-Q99 -> 0.17647059
A100: Hayden | B100: Fringe | C100: 1 | D100: 2019 | E100: 1 | F100: 3 | G100: 1 | H100: 2 | I100: 0 | J100: 0 | K100: 1 | L100: 1 | M100: 5 | N100: 3 | O100: 0 | P100: 0 | Q100: =IF(F100=0,0,H100/F100) -> 0.66666667 | R100: =IF(F100+O100=0,0,(H100+O100)/(F100+O100)) -> 0.66666667 | S100: =IF(F100=0,0,M100/F100) -> 1.6666667 | T100: =S100+R100 -> 2.3333333 | U100: =S100-Q100 -> 1
A101: Eli | B101: Outsiders | C101: 1 | D101: 2026 | E101: 2 | F101: 5 | G101: 2 | H101: 2 | I101: 0 | J101: 0 | K101: 1 | L101: 1 | M101: 5 | N101: 2 | O101: 0 | P101: 0 | Q101: =IF(F101=0,0,H101/F101) -> 0.4 | R101: =IF(F101+O101=0,0,(H101+O101)/(F101+O101)) -> 0.4 | S101: =IF(F101=0,0,M101/F101) -> 1 | T101: =S101+R101 -> 1.4 | U101: =S101-Q101 -> 0.6
A102: Ezra | B102: Fringe | C102: 1 | D102: 2019 | E102: 3 | F102: 7 | G102: 5 | H102: 2 | I102: 0 | J102: 0 | K102: 1 | L102: 1 | M102: 5 | N102: 1 | O102: 4 | P102: 1 | Q102: =IF(F102=0,0,H102/F102) -> 0.28571429 | R102: =IF(F102+O102=0,0,(H102+O102)/(F102+O102)) -> 0.54545455 | S102: =IF(F102=0,0,M102/F102) -> 0.71428571 | T102: =S102+R102 -> 1.2597403 | U102: =S102-Q102 -> 0.42857143
A103: J T | B103: RipTide | C103: 1 | D103: 2018 | E103: 1 | F103: 3 | G103: 3 | H103: 2 | I103: 1 | J103: 0 | K103: 1 | L103: 2 | M103: 6 | N103: 3 | O103: 0 | P103: 0 | Q103: =IF(F103=0,0,H103/F103) -> 0.66666667 | R103: =IF(F103+O103=0,0,(H103+O103)/(F103+O103)) -> 0.66666667 | S103: =IF(F103=0,0,M103/F103) -> 2 | T103: =S103+R103 -> 2.6666667 | U103: =S103-Q103 -> 1.3333333
A104: R Rudzin | B104: Fringe | C104: 2 | D104: 2018,2021 | E104: 4 | F104: 7 | G104: 1 | H104: 1 | I104: 0 | J104: 0 | K104: 1 | L104: 1 | M104: 4 | N104: 4 | O104: 2 | P104: 1 | Q104: =IF(F104=0,0,H104/F104) -> 0.14285714 | R104: =IF(F104+O104=0,0,(H104+O104)/(F104+O104)) -> 0.33333333 | S104: =IF(F104=0,0,M104/F104) -> 0.57142857 | T104: =S104+R104 -> 0.9047619 | U104: =S104-Q104 -> 0.42857143
A105: B Brady Friend | B105: Bulkheads | C105: 2 | D105: 2024,2025 | E105: 2 | F105: 5 | G105: 1 | H105: 1 | I105: 0 | J105: 0 | K105: 1 | L105: 1 | M105: 4 | N105: 1 | O105: 1 | P105: 0 | Q105: =IF(F105=0,0,H105/F105) -> 0.2 | R105: =IF(F105+O105=0,0,(H105+O105)/(F105+O105)) -> 0.33333333 | S105: =IF(F105=0,0,M105/F105) -> 0.8 | T105: =S105+R105 -> 1.1333333 | U105: =S105-Q105 -> 0.6
A106: K Rotunno | B106: Dragons | C106: 8 | D106: 2018,2019,2021,2022,2023,2024,2025,2026 | E106: 61 | F106: 180 | G106: 60 | H106: 85 | I106: 31 | J106: 2 | K106: 1 | L106: 34 | M106: 123 | N106: 38 | O106: 37 | P106: 4 | Q106: =IF(F106=0,0,H106/F106) -> 0.47222222 | R106: =IF(F106+O106=0,0,(H106+O106)/(F106+O106)) -> 0.56221198 | S106: =IF(F106=0,0,M106/F106) -> 0.68333333 | T106: =S106+R106 -> 1.2455453 | U106: =S106-Q106 -> 0.21111111
... A477: Phil | B477: RipTide | C477: 1 | D477: 2018 | E477: 1 | F477: 1 | G477: 0 | H477: 0 | I477: 0 | J477: 0 | K477: 0 | L477: 0 | M477: 0 | N477: 0 | O477: 0 | P477: 0 | Q477: =IF(F477=0,0,H477/F477) -> 0 | R477: =IF(F477+O477=0,0,(H477+O477)/(F477+O477)) -> 0 | S477: =IF(F477=0,0,M477/F477) -> 0 | T477: =S477+R477 -> 0 | U477: =S477-Q477 -> 0
A478: M Chelli | B478: Dogfish | C478: 1 | D478: 2026 | E478: 12 | F478: 34 | G478: 2 | H478: 7 | I478: 0 | J478: 0 | K478: 0 | L478: 0 | M478: 7 | N478: 1 | O478: 2 | P478: 2 | Q478: =IF(F478=0,0,H478/F478) -> 0.20588235 | R478: =IF(F478+O478=0,0,(H478+O478)/(F478+O478)) -> 0.25 | S478: =IF(F478=0,0,M478/F478) -> 0.20588235 | T478: =S478+R478 -> 0.45588235 | U478: =S478-Q478 -> 0
A479: C Berman | B479: Outsiders | C479: 1 | D479: 2026 | E479: 1 | F479: 1 | G479: 0 | H479: 1 | I479: 0 | J479: 0 | K479: 0 | L479: 0 | M479: 1 | N479: 0 | O479: 0 | P479: 0 | Q479: =IF(F479=0,0,H479/F479) -> 1 | R479: =IF(F479+O479=0,0,(H479+O479)/(F479+O479)) -> 1 | S479: =IF(F479=0,0,M479/F479) -> 1 | T479: =S479+R479 -> 2 | U479: =S479-Q479 -> 0
A480: A Pitcher | B480: Dogfish | C480: 1 | D480: 2026 | E480: 2 | F480: 5 | G480: 0 | H480: 2 | I480: 0 | J480: 0 | K480: 0 | L480: 0 | M480: 2 | N480: 0 | O480: 0 | P480: 2 | Q480: =IF(F480=0,0,H480/F480) -> 0.4 | R480: =IF(F480+O480=0,0,(H480+O480)/(F480+O480)) -> 0.4 | S480: =IF(F480=0,0,M480/F480) -> 0.4 | T480: =S480+R480 -> 0.8 | U480: =S480-Q480 -> 0
A481: A Female | B481: Dogfish | C481: 1 | D481: 2026 | E481: 1 | F481: 1 | G481: 0 | H481: 0 | I481: 0 | J481: 0 | K481: 0 | L481: 0 | M481: 0 | N481: 0 | O481: 0 | P481: 0 | Q481: =IF(F481=0,0,H481/F481) -> 0 | R481: =IF(F481+O481=0,0,(H481+O481)/(F481+O481)) -> 0 | S481: =IF(F481=0,0,M481/F481) -> 0 | T481: =S481+R481 -> 0 | U481: =S481-Q481 -> 0
A482: B Coffey | B482: Dogfish | C482: 1 | D482: 2026 | E482: 1 | F482: 3 | G482: 0 | H482: 0 | I482: 0 | J482: 0 | K482: 0 | L482: 0 | M482: 0 | N482: 0 | O482: 0 | P482: 1 | Q482: =IF(F482=0,0,H482/F482) -> 0 | R482: =IF(F482+O482=0,0,(H482+O482)/(F482+O482)) -> 0 | S482: =IF(F482=0,0,M482/F482) -> 0 | T482: =S482+R482 -> 0 | U482: =S482-Q482 -> 0
A483: Alex Newman | B483: Dogfish | C483: 1 | D483: 2026 | E483: 1 | F483: 1 | G483: 0 | H483: 0 | I483: 0 | J483: 0 | K483: 0 | L483: 0 | M483: 0 | N483: 0 | O483: 1 | P483: 0 | Q483: =IF(F483=0,0,H483/F483) -> 0 | R483: =IF(F483+O483=0,0,(H483+O483)/(F483+O483)) -> 0.5 | S483: =IF(F483=0,0,M483/F483) -> 0 | T483: =S483+R483 -> 0.5 | U483: =S483-Q483 -> 0
A484: Leila Bender | B484: Fringe | C484: 3 | D484: 2024, 2025, 2026 | E484: 9 | F484: 16 | G484: 2 | H484: 2 | I484: 0 | J484: 0 | K484: 0 | L484: 0 | M484: 2 | N484: 0 | O484: 0 | P484: 0 | Q484: =IF(F484=0,0,H484/F484) -> 0.125 | R484: =IF(F484+O484=0,0,(H484+O484)/(F484+O484)) -> 0.125 | S484: =IF(F484=0,0,M484/F484) -> 0.125 | T484: =S484+R484 -> 0.25 | U484: =S484-Q484 -> 0
A485: N Modico | B485: RipTide | C485: 1 | D485: 2026 | E485: 1 | F485: 1 | G485: 1 | H485: 1 | I485: 0 | J485: 0 | K485: 0 | L485: 0 | M485: 1 | N485: 0 | O485: 1 | P485: 0 | Q485: =IF(F485=0,0,H485/F485) -> 1 | R485: =IF(F485+O485=0,0,(H485+O485)/(F485+O485)) -> 1 | S485: =IF(F485=0,0,M485/F485) -> 1 | T485: =S485+R485 -> 2 | U485: =S485-Q485 -> 0
A486: J Taub 2 | B486: Outsiders | C486: 1 | D486: 2026 | E486: 1 | F486: 2 | G486: 0 | H486: 0 | I486: 0 | J486: 0 | K486: 0 | L486: 0 | M486: 0 | N486: 0 | O486: 0 | P486: 0 | Q486: =IF(F486=0,0,H486/F486) -> 0 | R486: =IF(F486+O486=0,0,(H486+O486)/(F486+O486)) -> 0 | S486: =IF(F486=0,0,M486/F486) -> 0 | T486: =S486+R486 -> 0 | U486: =S486-Q486 -> 0
A487: R Boyle | B487: Clippers | C487: 1 | D487: 2026 | E487: 1 | F487: 2 | G487: 1 | H487: 1 | I487: 0 | J487: 0 | K487: 0 | L487: 0 | M487: 1 | N487: 0 | O487: 0 | P487: 0 | Q487: =IF(F487=0,0,H487/F487) -> 0.5 | R487: =IF(F487+O487=0,0,(H487+O487)/(F487+O487)) -> 0.5 | S487: =IF(F487=0,0,M487/F487) -> 0.5 | T487: =S487+R487 -> 1 | U487: =S487-Q487 -> 0
A488: D Friedman | B488: RipTide | C488: 1 | D488: 2026 | E488: 1 | F488: 2 | G488: 0 | H488: 0 | I488: 0 | J488: 0 | K488: 0 | L488: 0 | M488: 0 | N488: 0 | O488: 0 | P488: 0 | Q488: =IF(F488=0,0,H488/F488) -> 0 | R488: =IF(F488+O488=0,0,(H488+O488)/(F488+O488)) -> 0 | S488: =IF(F488=0,0,M488/F488) -> 0 | T488: =S488+R488 -> 0 | U488: =S488-Q488 -> 0
A489: J May | B489: RipTide | C489: 1 | D489: 2026 | E489: 1 | F489: 1 | G489: 0 | H489: 1 | I489: 0 | J489: 0 | K489: 0 | L489: 0 | M489: 1 | N489: 2 | O489: 0 | P489: 0 | Q489: =IF(F489=0,0,H489/F489) -> 1 | R489: =IF(F489+O489=0,0,(H489+O489)/(F489+O489)) -> 1 | S489: =IF(F489=0,0,M489/F489) -> 1 | T489: =S489+R489 -> 2 | U489: =S489-Q489 -> 0
...

Sheet Pitching by Season
A1: Season | B1: Team | C1: Pitcher | D1: G | E1: IP | F1: W | G1: L | H1: H | I1: R | J1: ER | K1: BB | L1: SO | M1: HR | N1: ERA | O1: WHIP | P1: K/7 | Q1: BB/7
A2: 2019 | B2: Bulkheads | C2: P Kahn | D2: 8 | E2: 52.2 | F2: 4 | G2: 3 | H2: 63 | I2: 38 | J2: 29 | K2: 32 | L2: 6 | M2: 7 | N2: 3.85 | O2: 1.8 | P2: 0.8 | Q2: 4.25
A3: 2019 | B3: Bulkheads | C3: S Carroll | D3: 2 | E3: 14 | F3: 2 | G3: 0 | H3: 11 | I3: 5 | J3: 4 | K3: 1 | L3: 2 | M3: 2 | N3: =IF(E3=0,0,J3*7/E3) -> 2 | O3: =IF(E3=0,0,(H3+K3)/E3) -> 0.85714286 | P3: =IF(E3=0,0,L3*7/E3) -> 1 | Q3: =IF(E3=0,0,K3*7/E3) -> 0.5
A4: 2019 | B4: Bulkheads | C4: J Metzler | D4: 5 | E4: 27.1 | F4: 1 | G4: 4 | H4: 44 | I4: 38 | J4: 31 | K4: 18 | L4: 5 | M4: 9 | N4: 7.94 | O4: 2.27 | P4: 1.28 | Q4: 4.61
A5: 2019 | B5: Clippers | C5: C Clarkin | D5: 13 | E5: 87.1 | F5: 10 | G5: 3 | H5: 110 | I5: 70 | J5: 60 | K5: 58 | L5: 19 | M5: 18 | N5: 4.81 | O5: 1.92 | P5: 1.52 | Q5: 4.65
A6: 2019 | B6: Clippers | C6: C Whitney | D6: 1 | E6: 1 | F6: 0 | G6: 0 | H6: 3 | I6: 1 | J6: 1 | K6: 1 | L6: 0 | M6: 0 | N6: =IF(E6=0,0,J6*7/E6) -> 7 | O6: =IF(E6=0,0,(H6+K6)/E6) -> 4 | P6: =IF(E6=0,0,L6*7/E6) -> 0 | Q6: =IF(E6=0,0,K6*7/E6) -> 7
A7: 2019 | B7: Clippers | C7: T Nagengast | D7: 1 | E7: 1 | F7: 0 | G7: 0 | H7: 0 | I7: 0 | J7: 0 | K7: 0 | L7: 0 | M7: 0 | N7: =IF(E7=0,0,J7*7/E7) -> 0 | O7: =IF(E7=0,0,(H7+K7)/E7) -> 0 | P7: =IF(E7=0,0,L7*7/E7) -> 0 | Q7: =IF(E7=0,0,K7*7/E7) -> 0
A8: 2019 | B8: Dogfish | C8: R Smith | D8: 12 | E8: 82.2 | F8: 7 | G8: 5 | H8: 87 | I8: 55 | J8: 42 | K8: 40 | L8: 22 | M8: 11 | N8: 3.56 | O8: 1.54 | P8: 1.86 | Q8: 3.39
A9: 2019 | B9: Dogfish | C9: Ryan | D9: 1 | E9: 7 | F9: 0 | G9: 1 | H9: 10 | I9: 10 | J9: 10 | K9: 7 | L9: 1 | M9: 2 | N9: =IF(E9=0,0,J9*7/E9) -> 10 | O9: =IF(E9=0,0,(H9+K9)/E9) -> 2.4285714 | P9: =IF(E9=0,0,L9*7/E9) -> 1 | Q9: =IF(E9=0,0,K9*7/E9) -> 7
A10: 2019 | B10: Dragons | C10: K Rotunno | D10: 5 | E10: 35.2 | F10: 3 | G10: 2 | H10: 45 | I10: 26 | J10: 24 | K10: 12 | L10: 5 | M10: 9 | N10: 4.71 | O10: 1.6 | P10: 0.98 | Q10: 2.36
A11: 2019 | B11: Dragons | C11: A Freifeld | D11: 3 | E11: 19 | F11: 2 | G11: 1 | H11: 20 | I11: 16 | J11: 10 | K11: 8 | L11: 1 | M11: 5 | N11: =IF(E11=0,0,J11*7/E11) -> 3.6842105 | O11: =IF(E11=0,0,(H11+K11)/E11) -> 1.4736842 | P11: =IF(E11=0,0,L11*7/E11) -> 0.36842105 | Q11: =IF(E11=0,0,K11*7/E11) -> 2.9473684
A12: 2019 | B12: Dragons | C12: M Sirovich | D12: 1 | E12: 7 | F12: 1 | G12: 0 | H12: 6 | I12: 2 | J12: 2 | K12: 2 | L12: 0 | M12: 0 | N12: =IF(E12=0,0,J12*7/E12) -> 2 | O12: =IF(E12=0,0,(H12+K12)/E12) -> 1.1428571 | P12: =IF(E12=0,0,L12*7/E12) -> 0 | Q12: =IF(E12=0,0,K12*7/E12) -> 2
A13: 2019 | B13: Dragons | C13: T Sconzo | D13: 3 | E13: 15 | F13: 1 | G13: 1 | H13: 19 | I13: 14 | J13: 10 | K13: 2 | L13: 1 | M13: 3 | N13: =IF(E13=0,0,J13*7/E13) -> 4.6666667 | O13: =IF(E13=0,0,(H13+K13)/E13) -> 1.4 | P13: =IF(E13=0,0,L13*7/E13) -> 0.46666667 | Q13: =IF(E13=0,0,K13*7/E13) -> 0.93333333
A14: 2019 | B14: Excitables | C14: A Cox | D14: 13 | E14: 90.1 | F14: 10 | G14: 3 | H14: 91 | I14: 55 | J14: 31 | K14: 50 | L14: 41 | M14: 12 | N14: 2.4 | O14: 1.56 | P14: 3.18 | Q14: 3.87
A15: 2019 | B15: Excitables | C15: C Posilico | D15: 1 | E15: 1 | F15: 0 | G15: 0 | H15: 1 | I15: 0 | J15: 0 | K15: 0 | L15: 0 | M15: 0 | N15: =IF(E15=0,0,J15*7/E15) -> 0 | O15: =IF(E15=0,0,(H15+K15)/E15) -> 1 | P15: =IF(E15=0,0,L15*7/E15) -> 0 | Q15: =IF(E15=0,0,K15*7/E15) -> 0
A16: 2019 | B16: Fringe | C16: Lenny Bender | D16: 12 | E16: 82.2 | F16: 4 | G16: 8 | H16: 122 | I16: 75 | J16: 54 | K16: 40 | L16: 15 | M16: 11 | N16: 4.57 | O16: 1.96 | P16: 1.27 | Q16: 3.39
A17: 2019 | B17: Fringe | C17: C Butler | D17: 1 | E17: 6 | F17: 0 | G17: 1 | H17: 7 | I17: 6 | J17: 4 | K17: 5 | L17: 0 | M17: 1 | N17: =IF(E17=0,0,J17*7/E17) -> 4.6666667 | O17: =IF(E17=0,0,(H17+K17)/E17) -> 2 | P17: =IF(E17=0,0,L17*7/E17) -> 0 | Q17: =IF(E17=0,0,K17*7/E17) -> 5.8333333
A18: 2019 | B18: Outsiders | C18: D Baum | D18: 9 | E18: 60 | F18: 3 | G18: 6 | H18: 71 | I18: 46 | J18: 32 | K18: 26 | L18: 14 | M18: 11 | N18: =IF(E18=0,0,J18*7/E18) -> 3.7333333 | O18: =IF(E18=0,0,(H18+K18)/E18) -> 1.6166667 | P18: =IF(E18=0,0,L18*7/E18) -> 1.6333333 | Q18: =IF(E18=0,0,K18*7/E18) -> 3.0333333
A19: 2019 | B19: Outsiders | C19: J Abrams | D19: 1 | E19: 6 | F19: 0 | G19: 1 | H19: 11 | I19: 9 | J19: 9 | K19: 6 | L19: 0 | M19: 2 | N19: =IF(E19=0,0,J19*7/E19) -> 10.5 | O19: =IF(E19=0,0,(H19+K19)/E19) -> 2.8333333 | P19: =IF(E19=0,0,L19*7/E19) -> 0 | Q19: =IF(E19=0,0,K19*7/E19) -> 7
A20: 2019 | B20: Outsiders | C20: M Perna | D20: 1 | E20: 1 | F20: 0 | G20: 0 | H20: 0 | I20: 0 | J20: 0 | K20: 1 | L20: 0 | M20: 0 | N20: =IF(E20=0,0,J20*7/E20) -> 0 | O20: =IF(E20=0,0,(H20+K20)/E20) -> 1 | P20: =IF(E20=0,0,L20*7/E20) -> 0 | Q20: =IF(E20=0,0,K20*7/E20) -> 7
A21: 2019 | B21: Outsiders | C21: R Perna | D21: 1 | E21: 6 | F21: 0 | G21: 1 | H21: 8 | I21: 6 | J21: 4 | K21: 1 | L21: 1 | M21: 1 | N21: =IF(E21=0,0,J21*7/E21) -> 4.6666667 | O21: =IF(E21=0,0,(H21+K21)/E21) -> 1.5 | P21: =IF(E21=0,0,L21*7/E21) -> 1.1666667 | Q21: =IF(E21=0,0,K21*7/E21) -> 1.1666667
A22: 2019 | B22: RipTide | C22: T Nagengast | D22: 8 | E22: 51.2 | F22: 1 | G22: 7 | H22: 82 | I22: 78 | J22: 58 | K22: 63 | L22: 13 | M22: 14 | N22: 7.86 | O22: 2.81 | P22: 1.76 | Q22: 8.54
A23: 2019 | B23: RipTide | C23: J Goldfarb | D23: 1 | E23: 1 | F23: 0 | G23: 0 | H23: 0 | I23: 0 | J23: 0 | K23: 3 | L23: 0 | M23: 0 | N23: =IF(E23=0,0,J23*7/E23) -> 0 | O23: =IF(E23=0,0,(H23+K23)/E23) -> 3 | P23: =IF(E23=0,0,L23*7/E23) -> 0 | Q23: =IF(E23=0,0,K23*7/E23) -> 21
A24: 2019 | B24: RipTide | C24: L Goldfarb | D24: 1 | E24: 4.1 | F24: 0 | G24: 1 | H24: 5 | I24: 9 | J24: 5 | K24: 11 | L24: 1 | M24: 0 | N24: 8.08 | O24: 3.69 | P24: 1.62 | Q24: 17.77
A25: 2019 | B25: RipTide | C25: O Monteleone | D25: 3 | E25: 3 | F25: 0 | G25: 0 | H25: 6 | I25: 3 | J25: 3 | K25: 2 | L25: 0 | M25: 1 | N25: =IF(E25=0,0,J25*7/E25) -> 7 | O25: =IF(E25=0,0,(H25+K25)/E25) -> 2.6666667 | P25: =IF(E25=0,0,L25*7/E25) -> 0 | Q25: =IF(E25=0,0,K25*7/E25) -> 4.6666667
A26: 2019 | B26: RipTide | C26: P Notaro | D26: 1 | E26: 6 | F26: 0 | G26: 1 | H26: 6 | I26: 6 | J26: 5 | K26: 4 | L26: 0 | M26: 1 | N26: =IF(E26=0,0,J26*7/E26) -> 5.8333333 | O26: =IF(E26=0,0,(H26+K26)/E26) -> 1.6666667 | P26: =IF(E26=0,0,L26*7/E26) -> 0 | Q26: =IF(E26=0,0,K26*7/E26) -> 4.6666667
A27: 2019 | B27: RipTide | C27: S Singer | D27: 1 | E27: 1.2 | F27: 0 | G27: 0 | H27: 0 | I27: 0 | J27: 0 | K27: 0 | L27: 0 | M27: 0 | N27: 0 | O27: 0 | P27: 0 | Q27: 0
A28: 2021 | B28: Bulkheads | C28: S Karp | D28: 5 | E28: 36 | F28: 4 | G28: 1 | H28: 38 | I28: 10 | J28: 6 | K28: 8 | L28: 2 | M28: 3 | N28: =IF(E28=0,0,J28*7/E28) -> 1.1666667 | O28: =IF(E28=0,0,(H28+K28)/E28) -> 1.2777778 | P28: =IF(E28=0,0,L28*7/E28) -> 0.38888889 | Q28: =IF(E28=0,0,K28*7/E28) -> 1.5555556
A29: 2021 | B29: Bulkheads | C29: P Kahn | D29: 4 | E29: 27 | F29: 3 | G29: 1 | H29: 41 | I29: 23 | J29: 14 | K29: 5 | L29: 2 | M29: 5 | N29: =IF(E29=0,0,J29*7/E29) -> 3.6296296 | O29: =IF(E29=0,0,(H29+K29)/E29) -> 1.7037037 | P29: =IF(E29=0,0,L29*7/E29) -> 0.51851852 | Q29: =IF(E29=0,0,K29*7/E29) -> 1.2962963
A30: 2021 | B30: Clippers | C30: C Clarkin | D30: 7 | E30: 35 | F30: 2 | G30: 5 | H30: 55 | I30: 30 | J30: 20 | K30: 18 | L30: 6 | M30: 4 | N30: =IF(E30=0,0,J30*7/E30) -> 4 | O30: =IF(E30=0,0,(H30+K30)/E30) -> 2.0857143 | P30: =IF(E30=0,0,L30*7/E30) -> 1.2 | Q30: =IF(E30=0,0,K30*7/E30) -> 3.6
A31: 2021 | B31: Clippers | C31: B Ehlers | D31: 4 | E31: 10 | F31: 1 | G31: 0 | H31: 16 | I31: 9 | J31: 7 | K31: 6 | L31: 3 | M31: 1 | N31: =IF(E31=0,0,J31*7/E31) -> 4.9 | O31: =IF(E31=0,0,(H31+K31)/E31) -> 2.2 | P31: =IF(E31=0,0,L31*7/E31) -> 2.1 | Q31: =IF(E31=0,0,K31*7/E31) -> 4.2
A32: 2021 | B32: Clippers | C32: T Nagengast | D32: 2 | E32: 8 | F32: 0 | G32: 0 | H32: 11 | I32: 2 | J32: 2 | K32: 4 | L32: 0 | M32: 0 | N32: =IF(E32=0,0,J32*7/E32) -> 1.75 | O32: =IF(E32=0,0,(H32+K32)/E32) -> 1.875 | P32: =IF(E32=0,0,L32*7/E32) -> 0 | Q32: =IF(E32=0,0,K32*7/E32) -> 3.5
A33: 2021 | B33: Dogfish | C33: D Hunter | D33: 4 | E33: 22 | F33: 1 | G33: 3 | H33: 43 | I33: 33 | J33: 25 | K33: 10 | L33: 0 | M33: 10 | N33: =IF(E33=0,0,J33*7/E33) -> 7.9545455 | O33: =IF(E33=0,0,(H33+K33)/E33) -> 2.4090909 | P33: =IF(E33=0,0,L33*7/E33) -> 0 | Q33: =IF(E33=0,0,K33*7/E33) -> 3.1818182
A34: 2021 | B34: Dogfish | C34: Justin: JO | D34: 5 | E34: 26.2 | F34: 1 | G34: 2 | H34: 40 | I34: 34 | J34: 23 | K34: 19 | L34: 2 | M34: 6 | N34: 6.04 | O34: 2.21 | P34: 0.53 | Q34: 4.99
A35: 2021 | B35: Dogfish | C35: Bob | D35: 2 | E35: 9 | F35: 0 | G35: 0 | H35: 17 | I35: 16 | J35: 13 | K35: 11 | L35: 0 | M35: 2 | N35: =IF(E35=0,0,J35*7/E35) -> 10.111111 | O35: =IF(E35=0,0,(H35+K35)/E35) -> 3.1111111 | P35: =IF(E35=0,0,L35*7/E35) -> 0 | Q35: =IF(E35=0,0,K35*7/E35) -> 8.5555556
A36: 2021 | B36: Dogfish | C36: D Mann | D36: 1 | E36: 1.1 | F36: 0 | G36: 1 | H36: 9 | I36: 17 | J36: 16 | K36: 7 | L36: 0 | M36: 3 | N36: 84 | O36: 12 | P36: 0 | Q36: 36.75
A37: 2021 | B37: Dogfish | C37: D Zabar | D37: 1 | E37: 1 | F37: 0 | G37: 1 | H37: 3 | I37: 4 | J37: 4 | K37: 3 | L37: 0 | M37: 0 | N37: =IF(E37=0,0,J37*7/E37) -> 28 | O37: =IF(E37=0,0,(H37+K37)/E37) -> 6 | P37: =IF(E37=0,0,L37*7/E37) -> 0 | Q37: =IF(E37=0,0,K37*7/E37) -> 21
A38: 2021 | B38: Dragons | C38: D Freedman | D38: 6 | E38: 30 | F38: 2 | G38: 1 | H38: 44 | I38: 35 | J38: 27 | K38: 14 | L38: 6 | M38: 5 | N38: =IF(E38=0,0,J38*7/E38) -> 6.3 | O38: =IF(E38=0,0,(H38+K38)/E38) -> 1.9333333 | P38: =IF(E38=0,0,L38*7/E38) -> 1.4 | Q38: =IF(E38=0,0,K38*7/E38) -> 3.2666667
A39: 2021 | B39: Dragons | C39: K Rotunno | D39: 4 | E39: 25.1 | F39: 2 | G39: 2 | H39: 22 | I39: 13 | J39: 11 | K39: 20 | L39: 6 | M39: 2 | N39: 3.04 | O39: 1.66 | P39: 1.66 | Q39: 5.53
A40: 2021 | B40: Dragons | C40: T Sconzo | D40: 3 | E40: 14.2 | F40: 1 | G40: 2 | H40: 23 | I40: 15 | J40: 11 | K40: 1 | L40: 1 | M40: 7 | N40: 5.25 | O40: 1.64 | P40: 0.48 | Q40: 0.48
...

Sheet Pitching Career
A1: Pitcher | B1: Team | C1: Seasons | D1: Years | E1: G | F1: IP | G1: W | H1: L | I1: H | J1: R | K1: ER | L1: BB | M1: SO | N1: HR | O1: ERA | P1: WHIP | Q1: K/7 | R1: BB/7
A2: A Cox | B2: Excitables | C2: 7 | D2: 2019,2021,2022,2023,2024,2025,2026 | E2: 82 | F2: 561.2 | G2: 56 | H2: 20 | I2: 557 | J2: 311 | K2: 222 | L2: 213 | M2: 243 | N2: 71 | O2: 2.77 | P2: 1.37 | Q2: 3.03 | R2: 2.65
A3: R Smith | B3: Fringe/Dogfish | C3: 7 | D3: 2019,2021,2022,2023,2024,2025,2026 | E3: 73 | F3: 490.1 | G3: 39 | H3: 26 | I3: 529 | J3: 330 | K3: 222 | L3: 243 | M3: 192 | N3: 43 | O3: 3.17 | P3: 1.57 | Q3: 2.74 | R3: 3.47
A4: C Clarkin | B4: Clippers | C4: 7 | D4: 2019,2021,2022,2023,2024,2025,2026 | E4: 82 | F4: 539.1 | G4: 40 | H4: 30 | I4: 725 | J4: 465 | K4: 323 | L4: 223 | M4: 82 | N4: 86 | O4: 4.19 | P4: 1.76 | Q4: 1.06 | R4: 2.89
A5: D Baum | B5: Outsiders | C5: 7 | D5: 2019,2021,2022,2023,2024,2025,2026 | E5: 70 | F5: 480.2 | G5: 34 | H5: 29 | I5: 493 | J5: 324 | K5: 245 | L5: 257 | M5: 113 | N5: 72 | O5: 3.57 | P5: 1.56 | Q5: 1.65 | R5: 3.74
A6: D Freedman | B6: Dragons | C6: 6 | D6: 2021,2022,2023,2024,2025,2026 | E6: 65 | F6: 410.1 | G6: 32 | H6: 22 | I6: 496 | J6: 355 | K6: 292 | L6: 298 | M6: 67 | N6: 60 | O6: 4.98 | P6: 1.94 | Q6: 1.14 | R6: 5.08
A7: S Karp | B7: Bulkheads | C7: 6 | D7: 2021,2022,2023,2024,2025,2026 | E7: 45 | F7: 308.2 | G7: 26 | H7: 12 | I7: 365 | J7: 188 | K7: 149 | L7: 65 | M7: 34 | N7: 60 | O7: 3.38 | P7: 1.39 | Q7: 0.77 | R7: 1.47
A8: P Kahn | B8: Bulkheads | C8: 7 | D8: 2019,2021,2022,2023,2024,2025,2026 | E8: 28 | F8: 185.2 | G8: 13 | H8: 11 | I8: 220 | J8: 135 | K8: 98 | L8: 72 | M8: 27 | N8: 27 | O8: 3.69 | P8: 1.57 | Q8: 1.02 | R8: 2.71
A9: T Nagengast | B9: RipTide | C9: 7 | D9: 2019,2021,2022,2023,2024,2025,2026 | E9: 38 | F9: 214 | G9: 9 | H9: 22 | I9: 302 | J9: 233 | K9: 180 | L9: 178 | M9: 33 | N9: 44 | O9: =IF(F9=0,0,K9*7/F9) -> 5.8878505 | P9: =IF(F9=0,0,(I9+L9)/F9) -> 2.2429907 | Q9: =IF(F9=0,0,M9*7/F9) -> 1.0794393 | R9: =IF(F9=0,0,L9*7/F9) -> 5.8224299
A10: Lenny Bender | B10: Fringe | C10: 5 | D10: 2019,2021,2024,2025,2026 | E10: 27 | F10: 173.1 | G10: 8 | H10: 17 | I10: 286 | J10: 180 | K10: 137 | L10: 65 | M10: 22 | N10: 38 | O10: 5.53 | P10: 2.03 | Q10: 0.89 | R10: 2.63
A11: S Carroll | B11: Bulkheads | C11: 5 | D11: 2019,2023,2024,2025,2026 | E11: 11 | F11: 72 | G11: 7 | H11: 2 | I11: 85 | J11: 52 | K11: 38 | L11: 13 | M11: 7 | N11: 12 | O11: =IF(F11=0,0,K11*7/F11) -> 3.6944444 | P11: =IF(F11=0,0,(I11+L11)/F11) -> 1.3611111 | Q11: =IF(F11=0,0,M11*7/F11) -> 0.68055556 | R11: =IF(F11=0,0,L11*7/F11) -> 1.2638889
A12: K Rotunno | B12: Dragons | C12: 6 | D12: 2019,2021,2023,2024,2025,2026 | E12: 19 | F12: 103 | G12: 5 | H12: 5 | I12: 121 | J12: 85 | K12: 78 | L12: 49 | M12: 17 | N12: 22 | O12: =IF(F12=0,0,K12*7/F12) -> 5.3009709 | P12: =IF(F12=0,0,(I12+L12)/F12) -> 1.6504854 | Q12: =IF(F12=0,0,M12*7/F12) -> 1.1553398 | R12: =IF(F12=0,0,L12*7/F12) -> 3.3300971
A13: J Starkey | B13: RipTide | C13: 6 | D13: 2021,2022,2023,2024,2025,2026 | E13: 26 | F13: 142 | G13: 5 | H13: 14 | I13: 201 | J13: 145 | K13: 100 | L13: 61 | M13: 18 | N13: 26 | O13: =IF(F13=0,0,K13*7/F13) -> 4.9295775 | P13: =IF(F13=0,0,(I13+L13)/F13) -> 1.8450704 | Q13: =IF(F13=0,0,M13*7/F13) -> 0.88732394 | R13: =IF(F13=0,0,L13*7/F13) -> 3.0070423
A14: O Monteleone | B14: RipTide | C14: 7 | D14: 2019,2021,2022,2023,2024,2025,2026 | E14: 23 | F14: 100.2 | G14: 4 | H14: 9 | I14: 147 | J14: 106 | K14: 73 | L14: 46 | M14: 9 | N14: 22 | O14: 5.08 | P14: 1.92 | Q14: 0.63 | R14: 3.2
A15: Bob | B15: Dogfish | C15: 4 | D15: 2021,2022,2023,2024 | E15: 17 | F15: 89.2 | G15: 3 | H15: 7 | I15: 113 | J15: 106 | K15: 71 | L15: 80 | M15: 12 | N15: 16 | O15: 5.54 | P15: 2.15 | Q15: 0.94 | R15: 6.25
A16: A Freifeld | B16: Dragons | C16: 4 | D16: 2019,2021,2023,2025 | E16: 7 | F16: 41 | G16: 2 | H16: 4 | I16: 56 | J16: 41 | K16: 32 | L16: 17 | M16: 2 | N16: 13 | O16: =IF(F16=0,0,K16*7/F16) -> 5.4634146 | P16: =IF(F16=0,0,(I16+L16)/F16) -> 1.7804878 | Q16: =IF(F16=0,0,M16*7/F16) -> 0.34146341 | R16: =IF(F16=0,0,L16*7/F16) -> 2.902439
A17: T Sconzo | B17: Dragons | C17: 3 | D17: 2019,2021,2023 | E17: 9 | F17: 40.1 | G17: 2 | H17: 3 | I17: 59 | J17: 43 | K17: 33 | L17: 6 | M17: 2 | N17: 15 | O17: 5.73 | P17: 1.61 | Q17: 0.35 | R17: 1.04
A18: J Metzler | B18: Bulkheads | C18: 1 | D18: 2019 | E18: 5 | F18: 27.1 | G18: 1 | H18: 4 | I18: 44 | J18: 38 | K18: 31 | L18: 18 | M18: 5 | N18: 9 | O18: 7.94 | P18: 2.27 | Q18: 1.28 | R18: 4.61
A19: B Karp | B19: Bulkheads | C19: 3 | D19: 2024,2025,2026 | E19: 8 | F19: 21 | G19: 1 | H19: 1 | I19: 31 | J19: 26 | K19: 19 | L19: 10 | M19: 5 | N19: 6 | O19: =IF(F19=0,0,K19*7/F19) -> 6.3333333 | P19: =IF(F19=0,0,(I19+L19)/F19) -> 1.952381 | Q19: =IF(F19=0,0,M19*7/F19) -> 1.6666667 | R19: =IF(F19=0,0,L19*7/F19) -> 3.3333333
A20: B Ehlers | B20: Clippers | C20: 1 | D20: 2021 | E20: 4 | F20: 10 | G20: 1 | H20: 0 | I20: 16 | J20: 9 | K20: 7 | L20: 6 | M20: 3 | N20: 1 | O20: =IF(F20=0,0,K20*7/F20) -> 4.9 | P20: =IF(F20=0,0,(I20+L20)/F20) -> 2.2 | Q20: =IF(F20=0,0,M20*7/F20) -> 2.1 | R20: =IF(F20=0,0,L20*7/F20) -> 4.2
A21: S Pszczolski | B21: Dogfish | C21: 2 | D21: 2025,2026 | E21: 18 | F21: 104.1 | G21: 1 | H21: 14 | I21: 172 | J21: 135 | K21: 102 | L21: 81 | M21: 15 | N21: 22 | O21: 6.84 | P21: 2.42 | Q21: 1.01 | R21: 5.43
A22: Justin: JO | B22: Dogfish | C22: 1 | D22: 2021 | E22: 5 | F22: 26.2 | G22: 1 | H22: 2 | I22: 40 | J22: 34 | K22: 23 | L22: 19 | M22: 2 | N22: 6 | O22: 6.04 | P22: 2.21 | Q22: 0.53 | R22: 4.99
A23: D Hunter | B23: Dogfish | C23: 1 | D23: 2021 | E23: 4 | F23: 22 | G23: 1 | H23: 3 | I23: 43 | J23: 33 | K23: 25 | L23: 10 | M23: 0 | N23: 10 | O23: =IF(F23=0,0,K23*7/F23) -> 7.9545455 | P23: =IF(F23=0,0,(I23+L23)/F23) -> 2.4090909 | Q23: =IF(F23=0,0,M23*7/F23) -> 0 | R23: =IF(F23=0,0,L23*7/F23) -> 3.1818182
A24: Ryan | B24: Dogfish | C24: 2 | D24: 2019,2023 | E24: 3 | F24: 21 | G24: 1 | H24: 2 | I24: 27 | J24: 24 | K24: 19 | L24: 14 | M24: 6 | N24: 6 | O24: =IF(F24=0,0,K24*7/F24) -> 6.3333333 | P24: =IF(F24=0,0,(I24+L24)/F24) -> 1.952381 | Q24: =IF(F24=0,0,M24*7/F24) -> 2 | R24: =IF(F24=0,0,L24*7/F24) -> 4.6666667
A25: M Kaufman | B25: Dogfish | C25: 1 | D25: 2022 | E25: 9 | F25: 41 | G25: 1 | H25: 7 | I25: 76 | J25: 59 | K25: 37 | L25: 19 | M25: 4 | N25: 6 | O25: =IF(F25=0,0,K25*7/F25) -> 6.3170732 | P25: =IF(F25=0,0,(I25+L25)/F25) -> 2.3170732 | Q25: =IF(F25=0,0,M25*7/F25) -> 0.68292683 | R25: =IF(F25=0,0,L25*7/F25) -> 3.2439024
A26: M Sirovich | B26: Dragons | C26: 1 | D26: 2019 | E26: 1 | F26: 7 | G26: 1 | H26: 0 | I26: 6 | J26: 2 | K26: 2 | L26: 2 | M26: 0 | N26: 0 | O26: =IF(F26=0,0,K26*7/F26) -> 2 | P26: =IF(F26=0,0,(I26+L26)/F26) -> 1.1428571 | Q26: =IF(F26=0,0,M26*7/F26) -> 0 | R26: =IF(F26=0,0,L26*7/F26) -> 2
A27: C Posilico | B27: Excitables | C27: 3 | D27: 2019,2021,2023 | E27: 5 | F27: 19 | G27: 1 | H27: 1 | I27: 27 | J27: 25 | K27: 22 | L27: 20 | M27: 5 | N27: 5 | O27: =IF(F27=0,0,K27*7/F27) -> 8.1052632 | P27: =IF(F27=0,0,(I27+L27)/F27) -> 2.4736842 | Q27: =IF(F27=0,0,M27*7/F27) -> 1.8421053 | R27: =IF(F27=0,0,L27*7/F27) -> 7.3684211
A28: R Perna | B28: Outsiders | C28: 5 | D28: 2019,2021,2022,2023,2024 | E28: 6 | F28: 23 | G28: 1 | H28: 2 | I28: 36 | J28: 29 | K28: 14 | L28: 11 | M28: 3 | N28: 4 | O28: =IF(F28=0,0,K28*7/F28) -> 4.2608696 | P28: =IF(F28=0,0,(I28+L28)/F28) -> 2.0434783 | Q28: =IF(F28=0,0,M28*7/F28) -> 0.91304348 | R28: =IF(F28=0,0,L28*7/F28) -> 3.3478261
A29: Missy | B29: Outsiders | C29: 2 | D29: 2024,2025 | E29: 4 | F29: 15.2 | G29: 1 | H29: 0 | I29: 15 | J29: 9 | K29: 9 | L29: 9 | M29: 2 | N29: 3 | O29: 4.02 | P29: 1.53 | Q29: 0.89 | R29: 4.02
A30: T Nagengast | B30: Clippers | C30: 3 | D30: 2019,2021,2022 | E30: 6 | F30: 24 | G30: 0 | H30: 2 | I30: 40 | J30: 30 | K30: 17 | L30: 13 | M30: 4 | N30: 6 | O30: =IF(F30=0,0,K30*7/F30) -> 4.9583333 | P30: =IF(F30=0,0,(I30+L30)/F30) -> 2.2083333 | Q30: =IF(F30=0,0,M30*7/F30) -> 1.1666667 | R30: =IF(F30=0,0,L30*7/F30) -> 3.7916667
A31: J Pasquerella | B31: Clippers | C31: 1 | D31: 2026 | E31: 1 | F31: 2 | G31: 0 | H31: 0 | I31: 4 | J31: 4 | K31: 3 | L31: 2 | M31: 0 | N31: 1 | O31: =IF(F31=0,0,K31*7/F31) -> 10.5 | P31: =IF(F31=0,0,(I31+L31)/F31) -> 3 | Q31: =IF(F31=0,0,M31*7/F31) -> 0 | R31: =IF(F31=0,0,L31*7/F31) -> 7
A32: Jackson | B32: Clippers | C32: 1 | D32: 2024 | E32: 1 | F32: 2 | G32: 0 | H32: 0 | I32: 3 | J32: 0 | K32: 0 | L32: 0 | M32: 0 | N32: 0 | O32: =IF(F32=0,0,K32*7/F32) -> 0 | P32: =IF(F32=0,0,(I32+L32)/F32) -> 1.5 | Q32: =IF(F32=0,0,M32*7/F32) -> 0 | R32: =IF(F32=0,0,L32*7/F32) -> 0
A33: C Whitney | B33: Clippers | C33: 1 | D33: 2019 | E33: 1 | F33: 1 | G33: 0 | H33: 0 | I33: 3 | J33: 1 | K33: 1 | L33: 1 | M33: 0 | N33: 0 | O33: =IF(F33=0,0,K33*7/F33) -> 7 | P33: =IF(F33=0,0,(I33+L33)/F33) -> 4 | Q33: =IF(F33=0,0,M33*7/F33) -> 0 | R33: =IF(F33=0,0,L33*7/F33) -> 7
A34: A Adams | B34: Dogfish | C34: 2 | D34: 2024,2025 | E34: 11 | F34: 55.1 | G34: 0 | H34: 6 | I34: 83 | J34: 77 | K34: 57 | L34: 45 | M34: 12 | N34: 20 | O34: 7.21 | P34: 2.31 | Q34: 1.52 | R34: 5.69
A35: Knot Bob | B35: Dogfish | C35: 2 | D35: 2023,2024 | E35: 7 | F35: 27.1 | G35: 0 | H35: 1 | I35: 51 | J35: 45 | K35: 39 | L35: 23 | M35: 1 | N35: 11 | O35: 9.99 | P35: 2.71 | Q35: 0.26 | R35: 5.89
A36: Sean | B36: Dogfish | C36: 1 | D36: 2023 | E36: 2 | F36: 7.2 | G36: 0 | H36: 1 | I36: 12 | J36: 13 | K36: 12 | L36: 7 | M36: 1 | N36: 3 | O36: 10.96 | P36: 2.48 | Q36: 0.91 | R36: 6.39
A37: D Mann | B37: Dogfish | C37: 2 | D37: 2021,2024 | E37: 6 | F37: 21.2 | G37: 0 | H37: 3 | I37: 51 | J37: 61 | K37: 39 | L37: 25 | M37: 1 | N37: 15 | O37: 12.6 | P37: 3.51 | Q37: 0.32 | R37: 8.08
A38: Alex | B38: Dogfish | C38: 1 | D38: 2023 | E38: 1 | F38: 1 | G38: 0 | H38: 0 | I38: 1 | J38: 0 | K38: 0 | L38: 0 | M38: 1 | N38: 0 | O38: =IF(F38=0,0,K38*7/F38) -> 0 | P38: =IF(F38=0,0,(I38+L38)/F38) -> 1 | Q38: =IF(F38=0,0,M38*7/F38) -> 7 | R38: =IF(F38=0,0,L38*7/F38) -> 0
A39: D Zabar | B39: Dogfish | C39: 1 | D39: 2021 | E39: 1 | F39: 1 | G39: 0 | H39: 1 | I39: 3 | J39: 4 | K39: 4 | L39: 3 | M39: 0 | N39: 0 | O39: =IF(F39=0,0,K39*7/F39) -> 28 | P39: =IF(F39=0,0,(I39+L39)/F39) -> 6 | Q39: =IF(F39=0,0,M39*7/F39) -> 0 | R39: =IF(F39=0,0,L39*7/F39) -> 21
A40: J Shire | B40: Dragons | C40: 1 | D40: 2026 | E40: 2 | F40: 2.2 | G40: 0 | H40: 0 | I40: 5 | J40: 3 | K40: 3 | L40: 0 | M40: 2 | N40: 2 | O40: 7.88 | P40: 1.88 | Q40: 5.25 | R40: 0
...

Sheet Team by Season
A1: Season | B1: Team | C1: W | D1: L | E1: T | F1: Win% | G1: RS | H1: RA | I1: Diff | J1: R/G | K1: RA/G | L1: AB | M1: H | N1: 2B | O1: 3B | P1: HR | Q1: Team AVG | R1: IP | S1: ERA | T1: K | U1: BB
A2: 2026 | B2: Outsiders | C2: 12 | D2: 2 | E2: 0 | F2: =IF(C2+D2+E2=0,0,C2/(C2+D2+E2)) -> 0.85714286 | G2: =SUMIFS('Batting by Season'!$F:$F,'Batting by Season'!$A:$A,$A2,'Batting by Season'!$B:$B,$B2) -> 135 | H2: =SUMIFS('Pitching by Season'!$I:$I,'Pitching by Season'!$A:$A,$A2,'Pitching by Season'!$B:$B,$B2) -> 60 | I2: =G2-H2 -> 75 | J2: =IF(C2+D2+E2=0,0,G2/(C2+D2+E2)) -> 9.6428571 | K2: =IF(C2+D2+E2=0,0,H2/(C2+D2+E2)) -> 4.2857143 | L2: =SUMIFS('Batting by Season'!$E:$E,'Batting by Season'!$A:$A,$A2,'Batting by Season'!$B:$B,$B2) -> 474 | M2: =SUMIFS('Batting by Season'!$G:$G,'Batting by Season'!$A:$A,$A2,'Batting by Season'!$B:$B,$B2) -> 173 | N2: =SUMIFS('Batting by Season'!$H:$H,'Batting by Season'!$A:$A,$A2,'Batting by Season'!$B:$B,$B2) -> 41 | O2: =SUMIFS('Batting by Season'!$I:$I,'Batting by Season'!$A:$A,$A2,'Batting by Season'!$B:$B,$B2) -> 1 | P2: =SUMIFS('Batting by Season'!$J:$J,'Batting by Season'!$A:$A,$A2,'Batting by Season'!$B:$B,$B2) -> 22 | Q2: =IF(L2=0,0,M2/L2) -> 0.3649789 | R2: =SUMIFS('Pitching by Season'!$E:$E,'Pitching by Season'!$A:$A,$A2,'Pitching by Season'!$B:$B,$B2) -> 101 | S2: =IF(R2=0,0,SUMIFS('Pitching by Season'!$J:$J,'Pitching by Season'!$A:$A,$A2,'Pitching by Season'!$B:$B,$B2)*7/R2) -> 2.980198 | T2: =SUMIFS('Pitching by Season'!$L:$L,'Pitching by Season'!$A:$A,$A2,'Pitching by Season'!$B:$B,$B2) -> 19 | U2: =SUMIFS('Pitching by Season'!$K:$K,'Pitching by Season'!$A:$A,$A2,'Pitching by Season'!$B:$B,$B2) -> 36
A3: 2026 | B3: Excitables | C3: 7 | D3: 6 | E3: 0 | F3: =IF(C3+D3+E3=0,0,C3/(C3+D3+E3)) -> 0.53846154 | G3: =SUMIFS('Batting by Season'!$F:$F,'Batting by Season'!$A:$A,$A3,'Batting by Season'!$B:$B,$B3) -> 89 | H3: =SUMIFS('Pitching by Season'!$I:$I,'Pitching by Season'!$A:$A,$A3,'Pitching by Season'!$B:$B,$B3) -> 56 | I3: =G3-H3 -> 33 | J3: =IF(C3+D3+E3=0,0,G3/(C3+D3+E3)) -> 6.8461538 | K3: =IF(C3+D3+E3=0,0,H3/(C3+D3+E3)) -> 4.3076923 | L3: =SUMIFS('Batting by Season'!$E:$E,'Batting by Season'!$A:$A,$A3,'Batting by Season'!$B:$B,$B3) -> 379 | M3: =SUMIFS('Batting by Season'!$G:$G,'Batting by Season'!$A:$A,$A3,'Batting by Season'!$B:$B,$B3) -> 114 | N3: =SUMIFS('Batting by Season'!$H:$H,'Batting by Season'!$A:$A,$A3,'Batting by Season'!$B:$B,$B3) -> 28 | O3: =SUMIFS('Batting by Season'!$I:$I,'Batting by Season'!$A:$A,$A3,'Batting by Season'!$B:$B,$B3) -> 1 | P3: =SUMIFS('Batting by Season'!$J:$J,'Batting by Season'!$A:$A,$A3,'Batting by Season'!$B:$B,$B3) -> 27 | Q3: =IF(L3=0,0,M3/L3) -> 0.30079156 | R3: =SUMIFS('Pitching by Season'!$E:$E,'Pitching by Season'!$A:$A,$A3,'Pitching by Season'!$B:$B,$B3) -> 85 | S3: =IF(R3=0,0,SUMIFS('Pitching by Season'!$J:$J,'Pitching by Season'!$A:$A,$A3,'Pitching by Season'!$B:$B,$B3)*7/R3) -> 2.9647059 | T3: =SUMIFS('Pitching by Season'!$L:$L,'Pitching by Season'!$A:$A,$A3,'Pitching by Season'!$B:$B,$B3) -> 47 | U3: =SUMIFS('Pitching by Season'!$K:$K,'Pitching by Season'!$A:$A,$A3,'Pitching by Season'!$B:$B,$B3) -> 23
A4: 2026 | B4: Clippers | C4: 10 | D4: 4 | E4: 0 | F4: =IF(C4+D4+E4=0,0,C4/(C4+D4+E4)) -> 0.71428571 | G4: =SUMIFS('Batting by Season'!$F:$F,'Batting by Season'!$A:$A,$A4,'Batting by Season'!$B:$B,$B4) -> 141 | H4: =SUMIFS('Pitching by Season'!$I:$I,'Pitching by Season'!$A:$A,$A4,'Pitching by Season'!$B:$B,$B4) -> 100 | I4: =G4-H4 -> 41 | J4: =IF(C4+D4+E4=0,0,G4/(C4+D4+E4)) -> 10.071429 | K4: =IF(C4+D4+E4=0,0,H4/(C4+D4+E4)) -> 7.1428571 | L4: =SUMIFS('Batting by Season'!$E:$E,'Batting by Season'!$A:$A,$A4,'Batting by Season'!$B:$B,$B4) -> 477 | M4: =SUMIFS('Batting by Season'!$G:$G,'Batting by Season'!$A:$A,$A4,'Batting by Season'!$B:$B,$B4) -> 181 | N4: =SUMIFS('Batting by Season'!$H:$H,'Batting by Season'!$A:$A,$A4,'Batting by Season'!$B:$B,$B4) -> 33 | O4: =SUMIFS('Batting by Season'!$I:$I,'Batting by Season'!$A:$A,$A4,'Batting by Season'!$B:$B,$B4) -> 0 | P4: =SUMIFS('Batting by Season'!$J:$J,'Batting by Season'!$A:$A,$A4,'Batting by Season'!$B:$B,$B4) -> 36 | Q4: =IF(L4=0,0,M4/L4) -> 0.37945493 | R4: =SUMIFS('Pitching by Season'!$E:$E,'Pitching by Season'!$A:$A,$A4,'Pitching by Season'!$B:$B,$B4) -> 96 | S4: =IF(R4=0,0,SUMIFS('Pitching by Season'!$J:$J,'Pitching by Season'!$A:$A,$A4,'Pitching by Season'!$B:$B,$B4)*7/R4) -> 4.5208333 | T4: =SUMIFS('Pitching by Season'!$L:$L,'Pitching by Season'!$A:$A,$A4,'Pitching by Season'!$B:$B,$B4) -> 11 | U4: =SUMIFS('Pitching by Season'!$K:$K,'Pitching by Season'!$A:$A,$A4,'Pitching by Season'!$B:$B,$B4) -> 30
A5: 2026 | B5: Dragons | C5: 9 | D5: 5 | E5: 0 | F5: 0.643 | G5: 109 | H5: 93 | I5: 16 | J5: 7.79 | K5: 6.64 | L5: 427 | M5: 145 | N5: 46 | O5: 1 | P5: 14 | Q5: 0.34 | R5: 92 | S5: 5.93 | T5: 17 | U5: 81
A6: 2026 | B6: Fringe | C6: 6 | D6: 8 | E6: 0 | F6: =IF(C6+D6+E6=0,0,C6/(C6+D6+E6)) -> 0.42857143 | G6: =SUMIFS('Batting by Season'!$F:$F,'Batting by Season'!$A:$A,$A6,'Batting by Season'!$B:$B,$B6) -> 69 | H6: =SUMIFS('Pitching by Season'!$I:$I,'Pitching by Season'!$A:$A,$A6,'Pitching by Season'!$B:$B,$B6) -> 97 | I6: =G6-H6 -> -28 | J6: =IF(C6+D6+E6=0,0,G6/(C6+D6+E6)) -> 4.9285714 | K6: =IF(C6+D6+E6=0,0,H6/(C6+D6+E6)) -> 6.9285714 | L6: =SUMIFS('Batting by Season'!$E:$E,'Batting by Season'!$A:$A,$A6,'Batting by Season'!$B:$B,$B6) -> 396 | M6: =SUMIFS('Batting by Season'!$G:$G,'Batting by Season'!$A:$A,$A6,'Batting by Season'!$B:$B,$B6) -> 104 | N6: =SUMIFS('Batting by Season'!$H:$H,'Batting by Season'!$A:$A,$A6,'Batting by Season'!$B:$B,$B6) -> 11 | O6: =SUMIFS('Batting by Season'!$I:$I,'Batting by Season'!$A:$A,$A6,'Batting by Season'!$B:$B,$B6) -> 1 | P6: =SUMIFS('Batting by Season'!$J:$J,'Batting by Season'!$A:$A,$A6,'Batting by Season'!$B:$B,$B6) -> 15 | Q6: =IF(L6=0,0,M6/L6) -> 0.26262626 | R6: =SUMIFS('Pitching by Season'!$E:$E,'Pitching by Season'!$A:$A,$A6,'Pitching by Season'!$B:$B,$B6) -> 94 | S6: =IF(R6=0,0,SUMIFS('Pitching by Season'!$J:$J,'Pitching by Season'!$A:$A,$A6,'Pitching by Season'!$B:$B,$B6)*7/R6) -> 6.0319149 | T6: =SUMIFS('Pitching by Season'!$L:$L,'Pitching by Season'!$A:$A,$A6,'Pitching by Season'!$B:$B,$B6) -> 20 | U6: =SUMIFS('Pitching by Season'!$K:$K,'Pitching by Season'!$A:$A,$A6,'Pitching by Season'!$B:$B,$B6) -> 41
A7: 2026 | B7: Bulkheads | C7: 7 | D7: 7 | E7: 0 | F7: =IF(C7+D7+E7=0,0,C7/(C7+D7+E7)) -> 0.5 | G7: =SUMIFS('Batting by Season'!$F:$F,'Batting by Season'!$A:$A,$A7,'Batting by Season'!$B:$B,$B7) -> 84 | H7: =SUMIFS('Pitching by Season'!$I:$I,'Pitching by Season'!$A:$A,$A7,'Pitching by Season'!$B:$B,$B7) -> 95 | I7: =G7-H7 -> -11 | J7: =IF(C7+D7+E7=0,0,G7/(C7+D7+E7)) -> 6 | K7: =IF(C7+D7+E7=0,0,H7/(C7+D7+E7)) -> 6.7857143 | L7: =SUMIFS('Batting by Season'!$E:$E,'Batting by Season'!$A:$A,$A7,'Batting by Season'!$B:$B,$B7) -> 418 | M7: =SUMIFS('Batting by Season'!$G:$G,'Batting by Season'!$A:$A,$A7,'Batting by Season'!$B:$B,$B7) -> 116 | N7: =SUMIFS('Batting by Season'!$H:$H,'Batting by Season'!$A:$A,$A7,'Batting by Season'!$B:$B,$B7) -> 21 | O7: =SUMIFS('Batting by Season'!$I:$I,'Batting by Season'!$A:$A,$A7,'Batting by Season'!$B:$B,$B7) -> 0 | P7: =SUMIFS('Batting by Season'!$J:$J,'Batting by Season'!$A:$A,$A7,'Batting by Season'!$B:$B,$B7) -> 20 | Q7: =IF(L7=0,0,M7/L7) -> 0.27751196 | R7: 96.7 | S7: =IF(R7=0,0,SUMIFS('Pitching by Season'!$J:$J,'Pitching by Season'!$A:$A,$A7,'Pitching by Season'!$B:$B,$B7)*7/R7) -> 5.8634953 | T7: =SUMIFS('Pitching by Season'!$L:$L,'Pitching by Season'!$A:$A,$A7,'Pitching by Season'!$B:$B,$B7) -> 13 | U7: =SUMIFS('Pitching by Season'!$K:$K,'Pitching by Season'!$A:$A,$A7,'Pitching by Season'!$B:$B,$B7) -> 27
A8: 2026 | B8: RipTide | C8: 2 | D8: 9 | E8: 0 | F8: =IF(C8+D8+E8=0,0,C8/(C8+D8+E8)) -> 0.18181818 | G8: =SUMIFS('Batting by Season'!$F:$F,'Batting by Season'!$A:$A,$A8,'Batting by Season'!$B:$B,$B8) -> 60 | H8: =SUMIFS('Pitching by Season'!$I:$I,'Pitching by Season'!$A:$A,$A8,'Pitching by Season'!$B:$B,$B8) -> 107 | I8: =G8-H8 -> -47 | J8: =IF(C8+D8+E8=0,0,G8/(C8+D8+E8)) -> 5.4545455 | K8: =IF(C8+D8+E8=0,0,H8/(C8+D8+E8)) -> 9.7272727 | L8: =SUMIFS('Batting by Season'!$E:$E,'Batting by Season'!$A:$A,$A8,'Batting by Season'!$B:$B,$B8) -> 321 | M8: =SUMIFS('Batting by Season'!$G:$G,'Batting by Season'!$A:$A,$A8,'Batting by Season'!$B:$B,$B8) -> 79 | N8: =SUMIFS('Batting by Season'!$H:$H,'Batting by Season'!$A:$A,$A8,'Batting by Season'!$B:$B,$B8) -> 9 | O8: =SUMIFS('Batting by Season'!$I:$I,'Batting by Season'!$A:$A,$A8,'Batting by Season'!$B:$B,$B8) -> 0 | P8: =SUMIFS('Batting by Season'!$J:$J,'Batting by Season'!$A:$A,$A8,'Batting by Season'!$B:$B,$B8) -> 17 | Q8: =IF(L8=0,0,M8/L8) -> 0.24610592 | R8: 70 | S8: =IF(R8=0,0,SUMIFS('Pitching by Season'!$J:$J,'Pitching by Season'!$A:$A,$A8,'Pitching by Season'!$B:$B,$B8)*7/R8) -> 8.9 | T8: =SUMIFS('Pitching by Season'!$L:$L,'Pitching by Season'!$A:$A,$A8,'Pitching by Season'!$B:$B,$B8) -> 9 | U8: =SUMIFS('Pitching by Season'!$K:$K,'Pitching by Season'!$A:$A,$A8,'Pitching by Season'!$B:$B,$B8) -> 47
A9: 2026 | B9: Dogfish | C9: 0 | D9: 12 | E9: 0 | F9: =IF(C9+D9+E9=0,0,C9/(C9+D9+E9)) -> 0 | G9: =SUMIFS('Batting by Season'!$F:$F,'Batting by Season'!$A:$A,$A9,'Batting by Season'!$B:$B,$B9) -> 40 | H9: =SUMIFS('Pitching by Season'!$I:$I,'Pitching by Season'!$A:$A,$A9,'Pitching by Season'!$B:$B,$B9) -> 119 | I9: =G9-H9 -> -79 | J9: =IF(C9+D9+E9=0,0,G9/(C9+D9+E9)) -> 3.3333333 | K9: =IF(C9+D9+E9=0,0,H9/(C9+D9+E9)) -> 9.9166667 | L9: =SUMIFS('Batting by Season'!$E:$E,'Batting by Season'!$A:$A,$A9,'Batting by Season'!$B:$B,$B9) -> 341 | M9: =SUMIFS('Batting by Season'!$G:$G,'Batting by Season'!$A:$A,$A9,'Batting by Season'!$B:$B,$B9) -> 92 | N9: =SUMIFS('Batting by Season'!$H:$H,'Batting by Season'!$A:$A,$A9,'Batting by Season'!$B:$B,$B9) -> 11 | O9: =SUMIFS('Batting by Season'!$I:$I,'Batting by Season'!$A:$A,$A9,'Batting by Season'!$B:$B,$B9) -> 0 | P9: =SUMIFS('Batting by Season'!$J:$J,'Batting by Season'!$A:$A,$A9,'Batting by Season'!$B:$B,$B9) -> 9 | Q9: =IF(L9=0,0,M9/L9) -> 0.26979472 | R9: 76 | S9: =IF(R9=0,0,SUMIFS('Pitching by Season'!$J:$J,'Pitching by Season'!$A:$A,$A9,'Pitching by Season'!$B:$B,$B9)*7/R9) -> 7.9210526 | T9: =SUMIFS('Pitching by Season'!$L:$L,'Pitching by Season'!$A:$A,$A9,'Pitching by Season'!$B:$B,$B9) -> 13 | U9: =SUMIFS('Pitching by Season'!$K:$K,'Pitching by Season'!$A:$A,$A9,'Pitching by Season'!$B:$B,$B9) -> 76
A10: 2025 | B10: Excitables | C10: 11 | D10: 3 | E10: 0 | F10: 0.786 | G10: 104 | H10: 43 | I10: 61 | J10: 7.43 | K10: 3.07 | L10: 423 | M10: 134 | N10: 31 | O10: 2 | P10: 21 | Q10: 0.317 | R10: 97.7 | S10: 2.51 | T10: 49 | U10: 20
A11: 2025 | B11: Bulkheads | C11: 10 | D11: 4 | E11: 0 | F11: 0.714 | G11: 100 | H11: 57 | I11: 43 | J11: 7.14 | K11: 4.07 | L11: 432 | M11: 139 | N11: 29 | O11: 0 | P11: 16 | Q11: 0.322 | R11: 97.3 | S11: 3.31 | T11: 13 | U11: 14
A12: 2025 | B12: Clippers | C12: 8 | D12: 5 | E12: 0 | F12: 0.615 | G12: 88 | H12: 71 | I12: 17 | J12: 6.77 | K12: 5.46 | L12: 379 | M12: 110 | N12: 18 | O12: 0 | P12: 27 | Q12: 0.29 | R12: 89 | S12: 4.01 | T12: 10 | U12: 20
A13: 2025 | B13: Outsiders | C13: 7 | D13: 5 | E13: 0 | F13: 0.583 | G13: 68 | H13: 43 | I13: 25 | J13: 5.67 | K13: 3.58 | L13: 375 | M13: 113 | N13: 26 | O13: 2 | P13: 13 | Q13: 0.301 | R13: 86.3 | S13: 2.84 | T13: 22 | U13: 36
A14: 2025 | B14: Dragons | C14: 8 | D14: 6 | E14: 0 | F14: 0.571 | G14: 79 | H14: 70 | I14: 9 | J14: 5.64 | K14: 5 | L14: 426 | M14: 134 | N14: 21 | O14: 0 | P14: 15 | Q14: 0.315 | R14: 95.7 | S14: 4.46 | T14: 17 | U14: 42
A15: 2025 | B15: Fringe | C15: 3 | D15: 9 | E15: 0 | F15: 0.25 | G15: 39 | H15: 91 | I15: -52 | J15: 3.25 | K15: 7.58 | L15: 343 | M15: 86 | N15: 14 | O15: 0 | P15: 14 | Q15: 0.251 | R15: 79 | S15: 6.2 | T15: 28 | U15: 38
A16: 2025 | B16: RipTide | C16: 2 | D16: 9 | E16: 0 | F16: 0.182 | G16: 21 | H16: 70 | I16: -49 | J16: 1.91 | K16: 6.36 | L16: 309 | M16: 71 | N16: 14 | O16: 0 | P16: 5 | Q16: 0.23 | R16: 65 | S16: 4.31 | T16: 11 | U16: 31
A17: 2025 | B17: Dogfish | C17: 1 | D17: 9 | E17: 0 | F17: 0.1 | G17: 24 | H17: 78 | I17: -54 | J17: 2.4 | K17: 7.8 | L17: 286 | M17: 61 | N17: 3 | O17: 2 | P17: 3 | Q17: 0.213 | R17: 70.7 | S17: 5.94 | T17: 10 | U17: 46
A18: 2024 | B18: Bulkheads | C18: 8 | D18: 3 | E18: 0 | F18: 0.727 | G18: 90 | H18: 65 | I18: 25 | J18: 8.18 | K18: 5.91 | L18: 340 | M18: 110 | N18: 14 | O18: 0 | P18: 22 | Q18: 0.324 | R18: 75.7 | S18: 3.89 | T18: 8 | U18: 26
A19: 2024 | B19: Excitables | C19: 7 | D19: 3 | E19: 0 | F19: 0.7 | G19: 84 | H19: 47 | I19: 37 | J19: 8.4 | K19: 4.7 | L19: 285 | M19: 81 | N19: 23 | O19: 0 | P19: 12 | Q19: 0.284 | R19: 71 | S19: 3.65 | T19: 19 | U19: 20
A20: 2024 | B20: Dragons | C20: 8 | D20: 4 | E20: 0 | F20: 0.667 | G20: 76 | H20: 52 | I20: 24 | J20: 6.33 | K20: 4.33 | L20: 405 | M20: 128 | N20: 27 | O20: 2 | P20: 6 | Q20: 0.316 | R20: 90 | S20: 3.34 | T20: 6 | U20: 70
A21: 2024 | B21: Fringe | C21: 6 | D21: 3 | E21: 0 | F21: 0.667 | G21: 67 | H21: 53 | I21: 14 | J21: 7.44 | K21: 5.89 | L21: 270 | M21: 85 | N21: 14 | O21: 0 | P21: 16 | Q21: 0.315 | R21: 62 | S21: 4.07 | T21: 18 | U21: 37
... A57: 2019 | B57: RipTide | C57: 1 | D57: 9 | E57: 0 | F57: 0.1 | G57: 37 | H57: 96 | I57: -59 | J57: 3.7 | K57: 9.6 | L57: 293 | M57: 72 | N57: 7 | O57: 0 | P57: 5 | Q57: 0.246 | R57: 67.7 | S57: 7.34 | T57: 14 | U57: 83
A58: 2018 | B58: Excitables | C58: 10 | D58: 3 | E58: 0 | F58: 0.769 | G58: 94 | H58: 56 | I58: 38 | J58: 7.23 | K58: 4.31 | L58: 372 | M58: 90 | N58: 18 | O58: 0 | P58: 17 | Q58: 0.242
A59: 2018 | B59: Dogfish | C59: 7 | D59: 4 | E59: 0 | F59: 0.636 | G59: 64 | H59: 67 | I59: -3 | J59: 5.82 | K59: 6.09 | L59: 327 | M59: 95 | N59: 9 | O59: 3 | P59: 18 | Q59: 0.291
A60: 2018 | B60: Clippers | C60: 6 | D60: 4 | E60: 0 | F60: 0.6 | G60: 61 | H60: 47 | I60: 14 | J60: 6.1 | K60: 4.7 | L60: 286 | M60: 82 | N60: 16 | O60: 2 | P60: 14 | Q60: 0.287
A61: 2018 | B61: Dragons | C61: 3 | D61: 3 | E61: 0 | F61: 0.5 | G61: 39 | H61: 30 | I61: 9 | J61: 6.5 | K61: 5 | L61: 183 | M61: 55 | N61: 11 | O61: 0 | P61: 2 | Q61: 0.301
A62: 2018 | B62: RipTide | C62: 3 | D62: 4 | E62: 0 | F62: 0.429 | G62: 37 | H62: 46 | I62: -9 | J62: 5.29 | K62: 6.57 | L62: 207 | M62: 55 | N62: 7 | O62: 0 | P62: 3 | Q62: 0.266
A63: 2018 | B63: Bulkheads | C63: 4 | D63: 6 | E63: 0 | F63: 0.4 | G63: 41 | H63: 51 | I63: -10 | J63: 4.1 | K63: 5.1 | L63: 261 | M63: 59 | N63: 5 | O63: 0 | P63: 9 | Q63: 0.226
A64: 2018 | B64: Outsiders | C64: 2 | D64: 6 | E64: 0 | F64: 0.25 | G64: 51 | H64: 64 | I64: -13 | J64: 6.38 | K64: 8 | L64: 253 | M64: 73 | N64: 10 | O64: 1 | P64: 11 | Q64: 0.289
A65: 2018 | B65: Fringe | C65: 2 | D65: 7 | E65: 0 | F65: 0.222 | G65: 29 | H65: 55 | I65: -26 | J65: 3.22 | K65: 6.11 | L65: 241 | M65: 53 | N65: 6 | O65: 0 | P65: 2 | Q65: 0.22

Sheet Team Career
A1: Team | B1: Seasons | C1: G | D1: W | E1: L | F1: T | G1: Win% | H1: RS | I1: RA | J1: Diff | K1: AB | L1: H | M1: 2B | N1: 3B | O1: HR | P1: Team AVG | Q1: IP | R1: ERA
A2: Excitables | B2: 8 | C2: 96 | D2: 68 | E2: 27 | F2: 1 | G2: 0.708 | H2: 707 | I2: 384 | J2: 323 | K2: 2798 | L2: 820 | M2: 162 | N2: 4 | O2: 145 | P2: 0.293 | Q2: 568.7 | R2: 2.98
A3: Bulkheads | B3: 8 | C3: 96 | D3: 57 | E3: 39 | F3: 0 | G3: 0.594 | H3: 620 | I3: 461 | J3: 159 | K3: 2829 | L3: 814 | M3: 142 | N3: 1 | O3: 126 | P3: 0.288 | Q3: 594.7 | R3: 3.66
A4: Clippers | B4: 8 | C4: 93 | D4: 53 | E4: 39 | F4: 1 | G4: 0.57 | H4: 639 | I4: 541 | J4: 98 | K4: 2792 | L4: 851 | M4: 131 | N4: 3 | O4: 170 | P4: 0.305 | Q4: 557.3 | R4: 4.28
A5: Dragons | B5: 8 | C5: 93 | D5: 50 | E5: 43 | F5: 0 | G5: 0.538 | H5: 539 | I5: 560 | J5: -21 | K5: 2813 | L5: 843 | M5: 162 | N5: 6 | O5: 60 | P5: 0.3 | Q5: 597.3 | R5: 5.16
A6: Fringe | B6: 8 | C6: 93 | D6: 44 | E6: 49 | F6: 0 | G6: 0.473 | H6: 499 | I6: 521 | J6: -22 | K6: 2709 | L6: 736 | M6: 102 | N6: 1 | O6: 127 | P6: 0.272 | Q6: 576.3 | R6: 3.98
A7: Outsiders | B7: 8 | C7: 84 | D7: 40 | E7: 44 | F7: 0 | G7: 0.476 | H7: 476 | I7: 447 | J7: 29 | K7: 2571 | L7: 746 | M7: 122 | N7: 6 | O7: 82 | P7: 0.29 | Q7: 529.7 | R7: 3.74
A8: RipTide | B8: 8 | C8: 79 | D8: 23 | E8: 56 | F8: 0 | G8: 0.291 | H8: 357 | I8: 587 | J8: -230 | K8: 2321 | L8: 595 | M8: 104 | N8: 6 | O8: 59 | P8: 0.256 | Q8: 472.7 | R8: 5.68
A9: Dogfish | B9: 8 | C9: 84 | D9: 23 | E9: 61 | F9: 0 | G9: 0.274 | H9: 352 | I9: 688 | J9: -336 | K9: 2443 | L9: 663 | M9: 90 | N9: 10 | O9: 61 | P9: 0.271 | Q9: 489 | R9: 6.36
